Workbook
Name Campaign_Code: 'Backup of Everyday RewardsFSC D'!$F$15
Name Campaign_Code: 'Everyday RewardsServices Data B'!$F$15
Name Campaign_Code: 'ONL Data Brief'!$F$15

Sheet Read Me First
B2: Read Me First
B4: Please note that as at 31-Jul-18 the Data Brief Form has been changed from one to three Data Brief Forms - one each for Woolworths Rewards or Frequent Shopper Club Customer Bases, Services Customer Bases, and Online Customer Bases, and other associated updates
B7: Tab 1: | C7: Data Brief Form - Woolworths Rewards or Frequent Shopper Club [FSC] Customer Bases
B8: Tab 2: | C8: Data Brief Form - Services Customer Bases
B9: Tab 3: | C9: Data Brief Form - Online Customer Bases
B11: Please use the Data Brief Form for the Business Area Customer Base your Campaign is targeting
B12: If your Campaign is targeting multiple Business Area Customer Bases, please complete the relevant Data Brief Form for each Business Area Customer Base

Sheet  1.0 BAU Campaign Set up
C6: Instructions:
C7: Please make a copy of the Form and Save to your Google Drive as: <Campaign Code>_1.0 Campaign Summary - BAU Campaign Set up Form_<v0.x>
C8: Complete the Form inputs
C9: Save the Form as a PDF by selecting: File > Download as > PDF document (.pdf)
C10: Upload to the Task in Simple
C13: Campaign Summary - BAU Campaign Set up
C15: Campaign Code
C16: =F20 -> OSP-3359
C18: Field Name | F18: Data
C20: cmpgn_code | F20: OSP-3359
C21: cmpgn_name | F21: OSP | N21: Note: Campaign Abbreviation
C22: description | F22: Points Multiplier
C23: cmpgn_type | F23: stretch | N23: Note: Default Value - Do Not Change
C24: cmpgn_mgr | F24: Danae Robinson
C25: cmpgn_mgr_email | F25: drobinson2@woolworths.com.au
C26: business_unit | F26: OSP
C27: lifecycle_start_dt | F27: 43957
C28: lifecycle_end_dt | F28: 43977
C29: source_system | F29: BAU
C30: fake_activn_ind | F30: N
C31: user_activn_ind | F31: Y
C32: pre_activn_ind | F32: N
C33: activn_type | F33: Single Week [S] | N33: Notes - Activation Type:
C34: audience_type | F34: Member | N34: - Single Week [S]: Used for Multiplier Offer Construct
C35: Activation Number of Days | F35: 11 | N35: - Parallel [P]: All Offers Start Date and End Dates are same. Used for Multiplier Offer Construct
C36: Sales Channel Type | F36: In store | N36: - Multi Week [M]: Offer Start Dates and End Dates are sequential, i.e.: the first offer ends then the second offer starts. Used for SOW and Continuity Offer Constructs. Not avaialable as at 16Nov18. Displays Calendar View
C37: Generate Control Group | F37: Yes | N37: - Choice [C]: Member chooses preferred Offer, e.g.: Points OR Google Mini
C38: Offer Length Days | F38: 7
C39: Redemption Limit | F39: 1
C40: Generate Promotion Codes | F40: No

Sheet Tab 1 Data Brief WR or FSC Cust
B5: Instructions:
B6: Please make a copy of the Form and Save to your Google Drive as: <Campaign Code>_2.0. Data - Data Brief Form_<v0.x>
B7: Complete the Form inputs
B8: Please Select "In" = Include, "Ex" = Exclude, where applicable. If a Data Field isn't relevant to the Campaign, leave it Blank
B9: Save the Form as a PDF by selecting: File > Download as > PDF document (.pdf) > Set Paper Size to A4 > Set Page Orientation to Portrait > Set Scale to Fit to height > EXPORT
B10: Upload to the Task in Simple
B12: Please Note that this Data Brief Form is for Campaigns targeting either the Woolworths Rewards Customer Base or Frequent Shoppers Club [FSC] Customer Base
B13: Data Brief Forms for Campaigns targeting a Services Customer Base or the Online Customer Bases are on Tabs 2 and 3 respectively
B14: If your Campaign is targeting multiple Business Area Customer Bases please complete the relevant Data Brief Form for each Business Area Customer Base
C17: 2.0 Data - Brief Form: Woolworths Rewards OR Frequent Shoppers Club [FSC] Customer Bases
C19: Campaign Code
C20: PMS-3372
B24: A | C24: Target Audience Selection
B26: A1 | C26: Business Area
C27: Target Customer Base
B28: In | C28: Woolworths Rewards
B29: . | C29: Frequent Shoppers Club [FSC]
B33: A3 | C33: Business Area Subscriptions (by Channel) | H33: Channels
H34: All Channel Inclusion/Exclusion | I34: Email | J34: Social Media (FB,Google Ad etc) | K34: Programmatic | L34: Reward Hub | M34: Rewards App | N34: WoW Shop App | O34: FB L2C | P34: SMS | Q34: Direct Mail | R34: Dockets
C35: Select Campaign Channels | H35: TRUE | I35: FALSE | J35: FALSE | K35: FALSE | L35: FALSE | M35: FALSE | N35: FALSE | O35: FALSE | P35: FALSE | Q35: FALSE | R35: FALSE
C37: Woolworths Rewards Subscriptions [includes FSC]
C38: Woolworths Rewards Communications | H38: . | I38: . | J38: . | K38: . | L38: . | M38: . | N38: . | O38: . | P38: . | Q38: . | R38: .
C39: Woolworths Supermarkets | H39: . | I39: . | J39: . | K39: . | L39: . | M39: . | N39: . | O39: . | P39: . | Q39: . | R39: .
C40: Select Business Subscriptions | H40: . | I40: . | J40: . | K40: . | L40: . | M40: . | N40: . | O40: . | P40: . | Q40: . | R40: .
C41: Select Business Subscriptions | H41: . | I41: . | J41: . | K41: . | L41: . | M41: . | N41: . | O41: . | P41: . | Q41: . | R41: .
C42: Select Business Subscriptions | H42: . | I42: . | J42: . | K42: . | L42: . | M42: . | N42: . | O42: . | P42: . | Q42: . | R42: .
C43: Select Business Subscriptions | H43: . | I43: . | J43: . | K43: . | L43: . | M43: . | N43: . | O43: . | P43: . | Q43: . | R43: .
C44: Select Business Subscriptions | H44: . | I44: . | J44: . | K44: . | L44: . | M44: . | N44: . | O44: . | P44: . | Q44: . | R44: .
C45: Select Business Subscriptions | H45: . | I45: . | J45: . | K45: . | L45: . | M45: . | N45: . | O45: . | P45: . | Q45: . | R45: .
C46: Select Business Subscriptions | H46: . | I46: . | J46: . | K46: . | L46: . | M46: . | N46: . | O46: . | P46: . | Q46: . | R46: .
C47: Select Business Subscriptions | H47: . | I47: . | J47: . | K47: . | L47: . | M47: . | N47: . | O47: . | P47: . | Q47: . | R47: .
B49: A4 | C49: Channel Subscriptions (by Channel, as they apply) | H49: . | I49: . | J49: . | K49: . | L49: . | M49: . | N49: . | O49: . | P49: . | Q49: . | R49: .
C50: Email Contact Preference | H50: . | I50: . | J50: . | K50: . | L50: . | M50: . | N50: . | O50: . | P50: . | Q50: . | R50: .
C51: Select Channel Subscriptions | H51: . | I51: . | J51: . | K51: . | L51: . | M51: . | N51: . | O51: . | P51: . | Q51: . | R51: .
C52: Select Channel Subscriptions | H52: . | I52: . | J52: . | K52: . | L52: . | M52: . | N52: . | O52: . | P52: . | Q52: . | R52: .
C53: Select Channel Subscriptions | H53: . | I53: . | J53: . | K53: . | L53: . | M53: . | N53: . | O53: . | P53: . | Q53: . | R53: .
C54: Select Channel Subscriptions | H54: . | I54: . | J54: . | K54: . | L54: . | M54: . | N54: . | O54: . | P54: . | Q54: . | R54: .
B57: A5 | C57: Other Exclusions | H57: . | I57: . | J57: . | K57: . | L57: . | M57: . | N57: . | O57: . | P57: . | Q57: . | R57: .
D58: Cancelled or Inactive Woolworths Reward Card | H58: . | I58: . | J58: . | K58: . | L58: . | M58: . | N58: . | O58: . | P58: . | Q58: . | R58: .
D59: Unregistered or Temp Card | H59: . | I59: . | J59: . | K59: . | L59: . | M59: . | N59: . | O59: . | P59: . | Q59: . | R59: .
...

Sheet Template Lookup
F2: Supers | H2: BWS | J2: BIGW | L2: EG/FUELCO | N2: Program Affiliates
C3: Target Audience Selection
C4: Business Area
A5: 1 | C5: Everyday Rewards
C7: Business Area Subscriptions (from website)
F8: Email | G8: Rewards App | H8: Email | I8: Rewards App | J8: Email | K8: Rewards App | L8: Email | M8: Rewards App | N8: Email | O8: Rewards App
C9: Everyday Rewards Subscriptions (includes FSC)
A10: 1 | C10: Unsubscribe from all Everyday Rewards communications | F10: Ex Optout | G10: Inc All | H10: Ex Optout | I10: Inc All | J10: Ex Optout | K10: Inc All | L10: Ex Optout | M10: Inc All | N10: Ex Optout | O10: Inc All
A11: =A10+1 -> 2 | C11: Exclusive offers and promotions | F11: Ex Optout | G11: Inc All | H11: Ex Optout | I11: Inc All | J11: Ex Optout | K11: Inc All | L11: Ex Optout | M11: Inc All | N11: Ex Optout | O11: Inc All
A12: =A11+1 -> 3 | C12: Woolworths Supermarkets | F12: Ex Optout | G12: Ex Optin | H12: . | I12: . | J12: . | K12: . | L12: . | M12: . | N12: . | O12: .
A13: =A12+1 -> 4 | C13: BWS | F13: . | G13: . | H13: Ex Optout | I13: Ex Optin | J13: . | K13: . | L13: . | M13: . | N13: . | O13: .
A14: =A13+1 -> 5 | C14: BIG W | F14: . | G14: . | H14: . | I14: . | J14: Ex Optout | K14: Ex Optin | L14: . | M14: . | N14: . | O14: .
A15: =A14+1 -> 6 | C15: Fuel | F15: . | G15: . | H15: . | I15: . | J15: . | K15: . | L15: Ex Optout | M15: Ex Optin | N15: . | O15: .
A16: =A15+1 -> 7 | C16: Program Affiliates | F16: . | G16: . | H16: . | I16: . | J16: . | K16: . | L16: . | M16: . | N16: Ex Optout | O16: Ex Optin
A17: =A16+1 -> 8 | C17: No liquor offers and promotions | F17: . | G17: . | H17: Ex Optout | I17: Ex Optout
C18: Channel Specific Subscriptions
A19: 1 | C19: Contact preference (website) - email | F19: Ex Optout | G19: Ex Optin | H19: Ex Optout | I19: Ex Optin | J19: Ex Optout | K19: Ex Optin | L19: Ex Optout | M19: Ex Optin | N19: Ex Optout | O19: Ex Optin
A20: =A19+1 -> 2 | F20: . | G20: . | H20: . | I20: . | J20: . | K20: . | L20: . | M20: . | N20: . | O20: .
A21: =A20+1 -> 3 | F21: . | G21: . | H21: . | I21: . | J21: . | K21: . | L21: . | M21: . | N21: . | O21: .
A22: =A21+1 -> 4 | F22: . | G22: . | H22: . | I22: . | J22: . | K22: . | L22: . | M22: . | N22: . | O22: .
C24: Exclusions (data specific)
F25: Email | G25: Rewards App | H25: Email | I25: Rewards App | J25: Email | K25: Rewards App | L25: Email | M25: Rewards App | N25: Email | O25: Rewards App
C26: Global Exclusions
A27: 1 | C27: Cancelled Woolworths Reward Card | F27: TRUE | G27: TRUE | H27: TRUE | I27: TRUE | J27: TRUE | K27: TRUE | L27: TRUE | M27: TRUE | N27: TRUE | O27: TRUE
A28: 2 | C28: Deceased | F28: TRUE | G28: TRUE | H28: TRUE | I28: TRUE | J28: TRUE | K28: TRUE | L28: TRUE | M28: TRUE | N28: TRUE | O28: TRUE
A29: =A28+1 -> 3 | C29: Age < 16 years | F29: TRUE | G29: TRUE | H29: TRUE | I29: TRUE | J29: TRUE | K29: TRUE | L29: TRUE | M29: TRUE | N29: TRUE | O29: TRUE
A30: =A29+1 -> 4 | C30: DC Universal Control Group | F30: TRUE | G30: FALSE | H30: TRUE | I30: FALSE | J30: TRUE | K30: FALSE | L30: TRUE | M30: FALSE | N30: TRUE | O30: FALSE
A31: =A30+1 -> 5 | C31: Competitor Email | F31: TRUE | G31: FALSE | H31: TRUE | I31: FALSE | J31: TRUE | K31: FALSE | L31: TRUE | M31: FALSE | N31: TRUE | O31: FALSE
C33: Standard Exclusions
F34: Email | G34: Rewards App | H34: Email | I34: Rewards App | J34: Email | K34: Rewards App | L34: Email | M34: Rewards App | N34: Email | O34: Rewards App
A35: 1 | C35: Age < 18 years | F35: TRUE | G35: TRUE | H35: TRUE | I35: TRUE | J35: TRUE | K35: TRUE | L35: TRUE | M35: TRUE | N35: TRUE | O35: TRUE
A36: =A35+1 -> 2 | C36: Age > 100 years or Missing | F36: TRUE | G36: TRUE | H36: TRUE | I36: TRUE | J36: TRUE | K36: TRUE | L36: TRUE | M36: TRUE | N36: TRUE | O36: TRUE
A37: =A36+1 -> 3 | C37: Overseas | F37: TRUE | G37: TRUE | H37: TRUE | I37: TRUE | J37: TRUE | K37: TRUE | L37: TRUE | M37: TRUE | N37: TRUE | O37: TRUE
A38: 4 | C38: Malicious First Name | F38: TRUE | G38: TRUE | H38: TRUE | I38: TRUE | J38: TRUE | K38: TRUE | L38: TRUE | M38: TRUE | N38: TRUE | O38: TRUE
A39: =A38+1 -> 5 | C39: Malicious Surname | F39: TRUE | G39: TRUE | H39: TRUE | I39: TRUE | J39: TRUE | K39: TRUE | L39: TRUE | M39: TRUE | N39: TRUE | O39: TRUE
A40: =A39+1 -> 6 | C40: =HYPERLINK("https://www.health.gov.au/health-topics/alcohol/about-alcohol/alcohol-laws-in-australia","Dry Postcodes (for Liquor Campaigns)") -> Dry Postcodes (for Liquor Campaigns) | F40: TRUE | G40: TRUE | H40: TRUE | I40: TRUE | J40: TRUE | K40: TRUE | L40: TRUE | M40: TRUE | N40: TRUE | O40: TRUE
A41: =A40+1 -> 7 | C41: Onboarding Journey (Joined Rewards in the last 30 days) | F41: TRUE | G41: TRUE | H41: TRUE | I41: TRUE | J41: TRUE | K41: TRUE | L41: TRUE | M41: TRUE | N41: TRUE | O41: TRUE
A42: =A41+1 -> 8 | C42: Staff | F42: FALSE | G42: FALSE | H42: FALSE | I42: FALSE | J42: FALSE | K42: FALSE | L42: FALSE | M42: FALSE | N42: FALSE | O42: FALSE
C44: Additional Email Standard Exclusions
F45: Email | G45: Rewards App | H45: Email | I45: Rewards App | J45: Email | K45: Rewards App | L45: Email | M45: Rewards App | N45: Email | O45: Rewards App
...

Sheet Menu
A1: Email | B1: =IFERROR(__xludf.DUMMYFUNCTION("importrange(""1sR5LUhmkYePdyssK1Op4xrpz2vCMaZ6yMgYZ5svxGfE"",""Control!B2"")"),"#REF!") -> #REF!
B2: 8
A5: Supers | B5: =if(A5="BWS","BWS",if(A5="XSell","XSell","ALL")) -> ALL
A6: Instructions: Step 0: Please create a copy of this template. Avoid modifying this copy. Step 1: Activate the scripts by clicking on the orange button. Once prompted for permissions, select your Woolworths account to proceed. If you are briefing in an ecom campaign, click on the blue button and skip the rest. Otherwise, proceed to Step 2. Step 2: Pick one or more channels that will be utilised by your campaign. By clicking on the icon(s). Click 'X' to de-select. Step 3: Pick a banner, likewise by clicking on an icon. Click 'X' to de-select. Step 4: Press the red button to load the initial configuration. This tool will set recommended settings by default. You are still responsible for reviewing and finalising campaign conditions as part of campaign setup. Need help filling up the data brief? Here is a guide
A7: Step 2: Pick Channel(s). Additional channels can be manually selected in the main sheet.
B8: Channel 1
B9: Channel 2
B10: Channel 3
B11: Channel 4
A17: Step 3: Pick banner
B18: Supermarkets | F18: Financial Services (Services BU) | L18: Petstock
B19: BWS | F19: Qantas | L19: Accor
B20: Big W | F20: Bupa
B21: EG/FuelCo | F21: Origin
B22: Caltex | F22: Healthy Life
B23: Pop-up Partner | F23: Customer Feedback (Survey)
B24: Cross-Banner | F24: MyDeal
B25: Service | F25: Milkrun
A31: Step 4: Run

Sheet Everyday RewardsServices Data B
B6: Instructions:
B7: [CCV-8914] - [Ampol Increase Frequency - Sep] - Data Brief
C11: 3.0 Data - Brief Form: Everyday Rewards OR Frequent Shoppers Club (FSC) Customer Base
A13: [SEQ]
C14: Campaign Set Up
A15: 1 | C15: Campaign Code | F15: CCV-1234
A16: =A15+1 -> 2 | C16: Campaign Stream (Auto) | F16: =LOWER(left($F$15,3)) -> ccv
A17: =A16+1 -> 3 | C17: Campaign Subscription (Unsub Link) | F17: [mydeal] - MyDeal | G17: =if(isna(vlookup(concatenate("ALLUnsub Parameter",Menu!A5),'Preference Lookup'!D155:E171,2,false)),"",vlookup(concatenate("ALLUnsub Parameter",Menu!A5),'Preference Lookup'!D12:E171,2,false)) -> #REF! | H17: =if(isna(vlookup(concatenate("ALLUnsub Parameter",Menu!A5),'Preference Lookup'!D155:E171,2,false)),"",vlookup(concatenate("ALLUnsub Parameter",Menu!A5),'Preference Lookup'!D155:E171,2,false)) -> #REF!
A18: =A17+1 -> 4 | C18: =HYPERLINK("https://docs.google.com/spreadsheets/d/1XQaTYaKkzuTidSYCj1Sr0cqNyuLL8kdKhd630ztvOYI/edit#gid=1329109951","Campaign Name / Type") -> Campaign Name / Type
A19: =A18+1 -> 5 | C19: Campaign Description | F19: Spend Stretch Campaign
A20: =A19+1 -> 6 | C20: Campaign Manager | F20: firstname.lastname@swiftfoods.com.au
A21: =A20+1 -> 7 | C21: Campaign Manager Email | F21: Firstname Lastname
A22: =A21+1 -> 8 | C22: Campaign Start Date | F22: 47401 | G22: =K22
A23: =A22+1 -> 9 | C23: Campaign End Date | F23: 47454 | G23: =K23
A24: =A23+1 -> 10 | C24: Campaign Duration (Sanity Check) | F24: =CONCATENATE(sum(F23-F22)," day(s)") -> 53 day(s)
A25: =A24+1 -> 11 | C25: Sales Channel Type | F25: Online
A26: =A25+1 -> 12 | C26: Activation Type | F26: Single [S]
A27: =A26+1 -> 13 | C27: Redemption Limit | F27: 1
A28: =A27+1 -> 14 | C28: Offer Length Days | F28: 1
A29: 15 | C29: User Activation | F29: TRUE | G29: Required for campaigns where customers need to activate their offers.
A30: =A29+1 -> 16 | C30: Pre-Activation | F30: TRUE | G30: Required for campaigns where the offers were pre-activated for customers
A31: =A30+1 -> 17 | C31: Generate Control Group | F31: TRUE | G31: Required for campaigns that measures incremental sales or modelling
A32: 19 | C32: Link to Precount JIRA | F32: FALSE
A33: 20 | C33: Other | F33: FALSE
C35: Analysis and Files
C36: Select Output Requirements
A37: 1 | C37: Waterfall Counts | F37: TRUE
A38: =A37+1 -> 2 | C38: Offer Summary | F38: TRUE
A39: =A38+1 -> 3 | C39: Sample Data File (SDF) | F39: TRUE
A40: =A39+1 -> 4 | C40: OUT02 Sample File | F40: TRUE | G40: "OUT02" is the name of the data pipeline we use for offer attachment.
A41: =A40+1 -> 5 | C41: Support Portal File | F41: FALSE
C43: Target Audience Selection
C44: Business Area
A45: 1 | C45: Everyday Rewards | F45: TRUE
C47: Business Area Subscriptions (from website)
H48: Email | I48: Push - Rewards App | J48: Rewards App | BD48: =H48 -> Email | BE48: =I48 -> Push - Rewards App | BF48: =J48 -> Rewards App | BG48: =K48
A50: 1 | C50: Fuel | H50: =if(isna(vlookup(concatenate("ALL",H$48,$C50),'Preference Lookup'!$D$3:$E$150,2,false)),".",vlookup(concatenate("ALL",H$48,$C50),'Preference Lookup'!$D$3:$E$150,2,false)) -> Ex Optout | I50: Ex Optout | J50: Ex Optout | K50: =if(isna(vlookup(concatenate("ALL",K$48,$C50),'Preference Lookup'!$D$3:$E$150,2,false)),".",vlookup(concatenate("ALL",K$48,$C50),'Preference Lookup'!$D$3:$E$150,2,false)) -> . | L50: . | BD50: =if(isna(vlookup(concatenate("ALL",BD$48,$C50),'Preference Lookup'!$D$3:$E$150,2,false)),".",vlookup(concatenate("ALL",BD$48,$C50),'Preference Lookup'!$D$3:$E$150,2,false)) -> Ex Optout | BE50: =if(isna(vlookup(concatenate("ALL",BE$48,$C50),'Preference Lookup'!$D$3:$E$150,2,false)),".",vlookup(concatenate("ALL",BE$48,$C50),'Preference Lookup'!$D$3:$E$150,2,false)) -> . | BF50: =if(isna(vlookup(concatenate("ALL",BF$48,$C50),'Preference Lookup'!$D$3:$E$150,2,false)),".",vlookup(concatenate("ALL",BF$48,$C50),'Preference Lookup'!$D$3:$E$150,2,false)) -> Inc All | BG50: =if(isna(vlookup(concatenate("ALL",BG$48,$C50),'Preference Lookup'!$D$3:$E$150,2,false)),".",vlookup(concatenate("ALL",BG$48,$C50),'Preference Lookup'!$D$3:$E$150,2,false)) -> .
A51: 1 | C51: Program Affiliates | H51: =if(isna(vlookup(concatenate("ALL",H$48,$C51),'Preference Lookup'!$D$3:$E$150,2,false)),".",vlookup(concatenate("ALL",H$48,$C51),'Preference Lookup'!$D$3:$E$150,2,false)) -> Ex Optout | I51: Inc All | J51: =if(isna(vlookup(concatenate("ALL",J$48,$C51),'Preference Lookup'!$D$3:$E$150,2,false)),".",vlookup(concatenate("ALL",J$48,$C51),'Preference Lookup'!$D$3:$E$150,2,false)) -> Inc All | K51: =if(isna(vlookup(concatenate("ALL",K$48,$C51),'Preference Lookup'!$D$3:$E$150,2,false)),".",vlookup(concatenate("ALL",K$48,$C51),'Preference Lookup'!$D$3:$E$150,2,false)) -> . | L51: . | BD51: =if(isna(vlookup(concatenate("ALL",BD$48,$C51),'Preference Lookup'!$D$3:$E$150,2,false)),".",vlookup(concatenate("ALL",BD$48,$C51),'Preference Lookup'!$D$3:$E$150,2,false)) -> Ex Optout | BE51: =if(isna(vlookup(concatenate("ALL",BE$48,$C51),'Preference Lookup'!$D$3:$E$150,2,false)),".",vlookup(concatenate("ALL",BE$48,$C51),'Preference Lookup'!$D$3:$E$150,2,false)) -> . | BF51: =if(isna(vlookup(concatenate("ALL",BF$48,$C51),'Preference Lookup'!$D$3:$E$150,2,false)),".",vlookup(concatenate("ALL",BF$48,$C51),'Preference Lookup'!$D$3:$E$150,2,false)) -> Inc All | BG51: =if(isna(vlookup(concatenate("ALL",BG$48,$C51),'Preference Lookup'!$D$3:$E$150,2,false)),".",vlookup(concatenate("ALL",BG$48,$C51),'Preference Lookup'!$D$3:$E$150,2,false)) -> .
H52: =if(isna(vlookup(concatenate("ALL",H$48,$C52),'Preference Lookup'!$D$3:$E$150,2,false)),".",vlookup(concatenate("ALL",H$48,$C52),'Preference Lookup'!$D$3:$E$150,2,false)) -> . | J52: =if(isna(vlookup(concatenate("ALL",J$48,$C52),'Preference Lookup'!$D$3:$E$150,2,false)),".",vlookup(concatenate("ALL",J$48,$C52),'Preference Lookup'!$D$3:$E$150,2,false)) -> . | K52: =if(isna(vlookup(concatenate("ALL",K$48,$C52),'Preference Lookup'!$D$3:$E$150,2,false)),".",vlookup(concatenate("ALL",K$48,$C52),'Preference Lookup'!$D$3:$E$150,2,false)) -> . | L52: . | BD52: =if(isna(vlookup(concatenate("ALL",BD$48,$C52),'Preference Lookup'!$D$3:$E$150,2,false)),".",vlookup(concatenate("ALL",BD$48,$C52),'Preference Lookup'!$D$3:$E$150,2,false)) -> . | BE52: =if(isna(vlookup(concatenate("ALL",BE$48,$C52),'Preference Lookup'!$D$3:$E$150,2,false)),".",vlookup(concatenate("ALL",BE$48,$C52),'Preference Lookup'!$D$3:$E$150,2,false)) -> . | BF52: =if(isna(vlookup(concatenate("ALL",BF$48,$C52),'Preference Lookup'!$D$3:$E$150,2,false)),".",vlookup(concatenate("ALL",BF$48,$C52),'Preference Lookup'!$D$3:$E$150,2,false)) -> . | BG52: =if(isna(vlookup(concatenate("ALL",BG$48,$C52),'Preference Lookup'!$D$3:$E$150,2,false)),".",vlookup(concatenate("ALL",BG$48,$C52),'Preference Lookup'!$D$3:$E$150,2,false)) -> .
H53: =if(isna(vlookup(concatenate("ALL",H$48,$C53),'Preference Lookup'!$D$3:$E$150,2,false)),".",vlookup(concatenate("ALL",H$48,$C53),'Preference Lookup'!$D$3:$E$150,2,false)) -> . | J53: =if(isna(vlookup(concatenate("ALL",J$48,$C53),'Preference Lookup'!$D$3:$E$150,2,false)),".",vlookup(concatenate("ALL",J$48,$C53),'Preference Lookup'!$D$3:$E$150,2,false)) -> . | K53: =if(isna(vlookup(concatenate("ALL",K$48,$C53),'Preference Lookup'!$D$3:$E$150,2,false)),".",vlookup(concatenate("ALL",K$48,$C53),'Preference Lookup'!$D$3:$E$150,2,false)) -> . | L53: . | BD53: =if(isna(vlookup(concatenate("ALL",BD$48,$C53),'Preference Lookup'!$D$3:$E$150,2,false)),".",vlookup(concatenate("ALL",BD$48,$C53),'Preference Lookup'!$D$3:$E$150,2,false)) -> . | BE53: =if(isna(vlookup(concatenate("ALL",BE$48,$C53),'Preference Lookup'!$D$3:$E$150,2,false)),".",vlookup(concatenate("ALL",BE$48,$C53),'Preference Lookup'!$D$3:$E$150,2,false)) -> . | BF53: =if(isna(vlookup(concatenate("ALL",BF$48,$C53),'Preference Lookup'!$D$3:$E$150,2,false)),".",vlookup(concatenate("ALL",BF$48,$C53),'Preference Lookup'!$D$3:$E$150,2,false)) -> . | BG53: =if(isna(vlookup(concatenate("ALL",BG$48,$C53),'Preference Lookup'!$D$3:$E$150,2,false)),".",vlookup(concatenate("ALL",BG$48,$C53),'Preference Lookup'!$D$3:$E$150,2,false)) -> .
...

Sheet Sheet24

Sheet Backup of Everyday RewardsFSC D
B6: Instructions:
B7: Make a copy: [Campaign Code] - [Campaign Description] - Data Brief
C11: 3.0 Data - Brief Form: Everyday Rewards OR Frequent Shoppers Club (FSC) Customer Base
A13: [SEQ]
C14: Campaign Set Up
A15: 1 | C15: Campaign Code | F15: cvm-9999
A16: =A15+1 -> 2 | C16: Campaign Stream (Auto) | F16: =LOWER(left($F$15,3)) -> cvm
A17: =A16+1 -> 3 | C17: Campaign Subscription (Unsub Link) | F17: =if(isna(vlookup(concatenate("ALLUnsub Parameter",Menu!A5),'Preference Lookup'!D155:E162,2,false)),"",vlookup(concatenate("ALLUnsub Parameter",Menu!A5),'Preference Lookup'!D155:E162,2,false)) -> #REF! | H17: =if(isna(vlookup(concatenate("ALLUnsub Parameter",Menu!A5),'Preference Lookup'!D155:E162,2,false)),"",vlookup(concatenate("ALLUnsub Parameter",Menu!A5),'Preference Lookup'!D155:E162,2,false)) -> #REF!
A18: =A17+1 -> 4 | C18: =HYPERLINK("https://docs.google.com/spreadsheets/d/1XQaTYaKkzuTidSYCj1Sr0cqNyuLL8kdKhd630ztvOYI/edit#gid=1329109951","Campaign Name / Type") -> Campaign Name / Type | G18: https://docs.google.com/spreadsheets/d/1XQaTYaKkzuTidSYCj1Sr0cqNyuLL8kdKhd630ztvOYI/edit#gid=1329109951
A19: =A18+1 -> 5 | C19: Campaign Description | F19: [enter]
A20: =A19+1 -> 6 | C20: Campaign Manager | F20: [enter]
A21: =A20+1 -> 7 | C21: Campaign Manager Email | F21: [enter]
A22: =A21+1 -> 8 | C22: Campaign Start Date | F22: 44000 | G22: =F22 -> 44000
A23: =A22+1 -> 9 | C23: Campaign End Date | F23: 44028 | G23: =F23 -> 44028
A24: =A23+1 -> 10 | C24: Campaign Duration (Sanity Check) | F24: =CONCATENATE(sum(F23-F22)," day(s)") -> 28 day(s)
A25: =A24+1 -> 11 | C25: Sales Channel Type | F25: Both
A26: =A25+1 -> 12 | C26: Activation Type | F26: Single [S] | G26: https://woolworthslimited.atlassian.net/wiki/spaces/CDD/pages/230424655/Offer+Attachment
A27: =A26+1 -> 13 | C27: Redemption Limit | F27: 1
A28: =A27+1 -> 14 | C28: Offer Length Days | F28: 1 | G28: https://woolworthslimited.atlassian.net/wiki/spaces/CDD/pages/230424655/Offer+Attachment
A29: 15 | C29: Fake Activation | F29: TRUE | G29: Required for Virtual Offers (VO) or testing purposes.
A30: =A29+1 -> 16 | C30: User Activation | F30: TRUE | G30: Required for campaigns where customers need to activate their offers. Also required for Virtual Offers.
A31: =A30+1 -> 17 | C31: Pre-Activation | F31: FALSE | G31: Generally used for ATL campaigns or when customers do not need to activate offers
A32: 18 | C32: Monitor Transactions (VO Only) | F32: FALSE
A33: 19 | C33: Generate Control Group | F33: FALSE | G33: Required for campaigns that measures incremental sales or modelling
A34: 20 | C34: Generate Promotion Codes | F34: FALSE
A35: =A34+1 -> 21 | C35: Link to Precount JIRA | F35: [enter]
A36: =A35+1 -> 22 | C36: Other
C38: Analysis and Files
C39: Select Output Requirements
A40: 1 | C40: Waterfall Counts | F40: TRUE
A41: =A40+1 -> 2 | C41: Offer Summary | F41: TRUE
A42: =A41+1 -> 3 | C42: Sample Data File (SDF) | F42: TRUE
A43: =A42+1 -> 4 | C43: OUT02 Sample File | F43: TRUE | G43: "OUT02" is the name of the data pipeline we use for offer attachment.
A44: =A43+1 -> 5 | C44: Support Portal File | F44: FALSE
C46: Target Audience Selection
C47: Business Area
A48: 1 | C48: Everyday Rewards | F48: TRUE
C50: Business Area Subscriptions (from website)
H51: Email | I51: Rewards App | M51: =H51 -> Email | N51: =I51 -> Rewards App | O51: =J51 | P51: =K51 | Q51: =L51
A53: 1 | C53: Unsubscribe from all Everyday Rewards communications | H53: =if(isna(vlookup(concatenate("ALL",H$51,$C53),'Preference Lookup'!$D$3:$E$150,2,false)),".",vlookup(concatenate("ALL",H$51,$C53),'Preference Lookup'!$D$3:$E$150,2,false)) -> Ex Optout | I53: =if(isna(vlookup(concatenate("ALL",I$51,$C53),'Preference Lookup'!$D$3:$E$150,2,false)),".",vlookup(concatenate("ALL",I$51,$C53),'Preference Lookup'!$D$3:$E$150,2,false)) -> Inc All | J53: =if(isna(vlookup(concatenate("ALL",J$51,$C53),'Preference Lookup'!$D$3:$E$150,2,false)),".",vlookup(concatenate("ALL",J$51,$C53),'Preference Lookup'!$D$3:$E$150,2,false)) -> . | L53: . | M53: =if(isna(vlookup(concatenate("ALL",M$51,$C53),'Preference Lookup'!$D$3:$E$150,2,false)),".",vlookup(concatenate("ALL",M$51,$C53),'Preference Lookup'!$D$3:$E$150,2,false)) -> Ex Optout | N53: =if(isna(vlookup(concatenate("ALL",N$51,$C53),'Preference Lookup'!$D$3:$E$150,2,false)),".",vlookup(concatenate("ALL",N$51,$C53),'Preference Lookup'!$D$3:$E$150,2,false)) -> Inc All | O53: =if(isna(vlookup(concatenate("ALL",O$51,$C53),'Preference Lookup'!$D$3:$E$150,2,false)),".",vlookup(concatenate("ALL",O$51,$C53),'Preference Lookup'!$D$3:$E$150,2,false)) -> . | P53: .
...

Sheet ONL Data Brief
Q1: =sum(Q2:Q11) -> 0
B6: Instructions:
B7: Make a copy: [Campaign Code] - [Campaign Description] - Data Brief
C11: 3.0 Data - Brief Form: eCOM (ONL) Customer Base
A13: [SEQ]
C14: Campaign Set Up
A15: 1 | C15: Campaign Code | F15: ONL-5887
A16: =A15+1 -> 2 | C16: Campaign Stream (Auto) | F16: =LOWER(left($F$15,3)) -> onl
A17: =A16+1 -> 3 | C17: Campaign Subscription (Unsub Link) | F17: onl
A18: =A17+1 -> 4 | C18: =HYPERLINK("https://docs.google.com/spreadsheets/d/1XQaTYaKkzuTidSYCj1Sr0cqNyuLL8kdKhd630ztvOYI/edit#gid=1329109951","Campaign Name / Type") -> Campaign Name / Type | F18: ONL
A19: =A18+1 -> 5 | C19: Campaign Description | F19: Sept Inactives Fresh Campaign
A20: =A19+1 -> 6 | C20: Campaign Manager | F20: Monica Kaczmarska
A21: =A20+1 -> 7 | C21: Campaign Manager Email | F21: mkaczmarska@woolworths.com.au
A22: =A21+1 -> 8 | C22: Campaign Start Date | F22: 44810 | G22: =K22
A23: =A22+1 -> 9 | C23: Campaign End Date | F23: 44824 | G23: =K23
A24: =A23+1 -> 10 | C24: Campaign Duration (Sanity Check) | F24: =CONCATENATE(sum(F23-F22)," day(s)") -> 14 day(s)
A25: =A24+1 -> 11 | C25: Sales Channel Type | F25: Online
A26: =A25+1 -> 12 | C26: Activation Type | F26: Single [S]
A27: =A26+1 -> 13 | C27: Offer Length Days | F27: 14
A28: =A27+1 -> 14 | C28: Control Group | E28: 5% evenly across Inactives & Active Churned Loyal | F28: TRUE
C30: Analysis and Files
C31: Select Output Requirements
A32: 1 | C32: Waterfall Counts | F32: TRUE
A33: =A32+1 -> 2 | C33: Offer Summary | F33: TRUE
A34: =A33+1 -> 3 | C34: Sample Data File (SDF) | F34: TRUE
C36: Target Audience Selection
C37: Business Area
A38: 1 | C38: Woolworths Online | F38: TRUE
C40: Business Area Subscriptions (from website)
H41: Email | I41: WOW App | J41: CRO (for ONL) | K41: . | L41: . | M41: . | N41: . | O41: .
C42: Everyday Rewards Subscriptions (includes FSC)
A43: 1 | C43: Online Customer | H43: Ex Optout | I43: Inc All | J43: Inc All | K43: . | L43: . | M43: . | N43: . | O43: .
A44: 2 | C44: Other Subscriptions | K44: . | L44: . | M44: . | N44: . | O44: .
C46: Exclusions (data specific)
H47: =H$41 -> Email | I47: =I41 -> WOW App | J47: =J41 -> CRO (for ONL) | K47: =K$41 -> . | L47: =L$41 -> . | M47: =M$41 -> . | N47: =N$41 -> . | O47: =O$41 -> .
C48: Global Exclusions
A49: 1 | C49: Active online customers | H49: FALSE | I49: TRUE | J49: FALSE | K49: FALSE | L49: FALSE | M49: FALSE | N49: FALSE | O49: FALSE
A50: 2 | C50: Invalid Shopper ID | H50: TRUE | I50: TRUE | J50: TRUE | K50: FALSE | L50: FALSE | M50: FALSE | N50: FALSE | O50: FALSE
A51: 3 | C51: Age < 16 years | H51: TRUE | I51: TRUE | J51: TRUE | K51: FALSE | L51: FALSE | M51: FALSE | N51: FALSE | O51: FALSE
A52: 4 | C52: CUST_B2B | H52: TRUE | I52: TRUE | J52: TRUE | K52: FALSE | L52: FALSE | M52: FALSE | N52: FALSE | O52: FALSE
...

Sheet meta
A1: CVM MACRO SEGMENT | B1: CVM LIFESTAGE | C1: subscriptions | D1: conditional fields friendly name | E1: offer_ids | F1: Channels | G1: Classification | H1: Call To Action Type | I1: send | J1: sub choices | K1: woolies subs | L1: channel subs | M1: channel sales type | N1: activation type | O1: online | P1: Channels 2 | Q1: YN | R1: TF
A2: HVHIGH | B2: MIDAGE SINGLES/COUPLES | C2: [bws] - BWS | D2: avg_8wk_spend | E2: offer_id_01 (fix) | F2: Select Channel | G2: Marketing | H2: All Selected Audience | I2: Send 1 | J2: Ex Optin | K2: Unsubscribe from all Everyday Rewards communications | L2: Contact preference (website) - email | M2: In Store | N2: Single [S] | O2: onl | P2: Select Channel | Q2: YES | R2: TRUE
A3: HVMED | B3: NEW FAMILIES | C3: [petrol] - Fuel | D3: activn_type | E3: offer_id_01 (fix) | F3: All Selected Channels | G3: Service | H3: Reminder to Shop and Activate | I3: Send 2 | J3: Ex Optout | K3: Woolworths Supermarkets | L3: Contact preference (website) - mail | M3: Online | N3: Parallel [P] | O3: catalogue | P3: Email | Q3: NO | R3: FALSE
A4: INACTIVE | B4: OLDER FAMILIES | C4: [woolworths] - Woolworths Supermarkets | D4: cell_number | E4: offer_id_01 (fix) | F4: Email | H4: Reminder to Shop nly | I4: Send 3 | J4: Inc All | K4: Liquor Offers | L4: Contact preference (website) - SMS | M4: Both | N4: Multi Week [M] | O4: Online Customer | P4: Rewards App
A5: LAPSED | B5: OLDER SINGLES/COUPLES | C5: [marketresearch] - Customer Feedback | D5: communication_channel | E5: offer_id_01 (fix) | F5: All Social (FB/IG + Google/Youtube) | H5: Reminder to Activate Only | I5: Send 4 | J5: . | K5: BWS | L5: Contact preference (website) - browser Cookies | N5: Choice [C] | O5: Catalogue Customer | P5: All Social (FB + Google)
A6: LOW | B6: RETIREES | C6: [homeinsurance] - Woolworths Home Insurance | D6: gender | E6: offer_id_01 (fix) | F6: FB/IG | H6: Congratulations/Information | I6: Send 5 | K6: Fuel | O6: Other Subscriptions | P6: Push
A7: LVHFA | B7: YOUNG FAMILIES | C7: [petinsurance] - Woolworths Pet Insurance | D7: lifestage | E7: offer_id_01 (fix) | F7: Google/Youtube | I7: Send 6 | K7: Exclusive offers and promotions | P7: Google
A8: LVHFB | B8: YOUNG SINGLES/COUPLES | C8: [lifeinsurance] - Woolworths Life Insurance | D8: lms_offer_id_multi | E8: offer_id_01 (fix) | F8: Display/Programatic | I8: Send 7 | K8: Customer Feedback | P8: Rewards Hub
A9: LVLF | C9: [carinsurance] - Woolworths Car Insurance | D9: macro_segment_curr | E9: offer_id_01 (fix) | F9: Push - WOW App | I9: Send 8 | K9: Woolworths Home Insurrance | P9: FB
F10: WOW App | P10: Tealium- All social
A11: LVLFB | C11: [travelinsurance] - Woolworths Travel Insurance | D11: no_liquor_content | F11: Push - Rewards App | I11: Send 9 | K11: Woolworths Pet Insurance | P11: Direct Mail
A12: MVHIGH | C12: [all] - Unsubscribe from all Everyday Rewards communications | D12: offeractivated | F12: Rewards App | I12: Send 10 | K12: Woolworths Life Insurance | P12: Dockets
A13: MVMEDA | C13: [bigw] - BIG W | D13: offercategory | F13: FB Wallet | I13: Send 11 | K13: Woolworths Car Insurance | P13: All Digital (Hubs + Apps)
A14: MVMEDB | C14: [programaffiliates] - Program Affiliates | D14: partner_abbrev | F14: Direct Mail | I14: Send 12 | K14: Woolworths Travel Insurance
C15: [edm] - Qantas Platinum Credit Card | D15: personalised_products | F15: SMS | I15: Send 13 | K15: BIG W
C16: [wowmobile] - Woolworths Mobile | D16: postcode | F16: CRO (for ONL) | I16: Send 14 | K16: Program Affiliates
C17: [wowpeoplediscount] - Everyday Rewards Plus | D17: preferred_store | F17: Other | I17: Send 15 | K17: Qantas Platinum Credit Card
C18: [n/a] Services BU | D18: preferred_store_name | F18: All Social (FB + Google) | I18: Send 16 | K18: Woolworths Mobile
C19: [qantas] - Qantas | D19: reward_currency_type | I19: Send 17 | K19: Everyday Rewards Plus
C20: [bupa] - Bupa | D20: reward_currency_type | I20: Send 18 | K20: Woolworths Funeral Insurance
C21: [origin] - Origin | D21: segment_code | I21: Send 19 | K21: Woolworths Landlords Insurance
C22: [marleyspoon] - Marley Spoon/Dinnerly | D22: segmentname | I22: Send 20 | K22: Everyday Platinum Credit Card
C23: [petculture] - Pet Culture | D23: spend_hurdle | K23: Prepaid Mastercard
C24: [superpharmacy] - SuperPharmacy | D24: spend_type | K24: Reloadable Prepaid Mastercard
C25: [healthylife] - Healthy Life | D25: state | K25: Services BU - Deduplicated Sendlist
C26: [popup] - Popup Partners | D26: store_nbr | K26: Qantas
C27: [mydeal] - MyDeal | D27: stream | K27: Bupa
D28: subscription | K28: Origin
D29: total_wow_reward | K29: Marley Spoon
D30: var1 | K30: Pet Culture
D31: var2 | K31: Super Pharmacy
D32: var3 | K32: Healthy Life
D33: var4 | K33: Popup Partners
D34: var5 | K34: Customer Feedback
D35: var6 | K35: MyDeal
D36: lylty_card_nbr
D37: promocode

Sheet Preference Lookup
A2: Key 1 - Banner | B2: Key 2 - Channel | C2: Key 3 - Line Item | D2: CompoundKey | E2: Value
A3: ALL | B3: Email | C3: Unsubscribe from all Everyday Rewards communications | D3: =CONCATENATE(A3,B3,C3) -> ALLEmailUnsubscribe from all Everyday Rewards communications | E3: Ex Optout | G3: ALLEmailUnsubscribe from all Everyday Rewards communications | H3: =vlookup(G3,D3:E150,2,false) -> Ex Optout
A4: ALL | B4: Rewards App | C4: Unsubscribe from all Everyday Rewards communications | D4: =CONCATENATE(A4,B4,C4) -> ALLRewards AppUnsubscribe from all Everyday Rewards communications | E4: Inc All | G4: ALLRewards AppUnsubscribe from all Everyday Rewards communications | H4: =vlookup(G4,D4:E174,1) -> ALLAll Social (FB + Google)Non Engaged (Has not clicked email in past 26 weeks)
A5: ALL | B5: Push | C5: Unsubscribe from all Everyday Rewards communications | D5: =CONCATENATE(A5,B5,C5) -> ALLPushUnsubscribe from all Everyday Rewards communications | E5: Inc All
A6: ALL | B6: All Social (FB + Google) | C6: Unsubscribe from all Everyday Rewards communications | D6: =CONCATENATE(A6,B6,C6) -> ALLAll Social (FB + Google)Unsubscribe from all Everyday Rewards communications | E6: Inc All | G6: ALLAll Social (FB + Google)Unsubscribe from all Everyday Rewards communications | H6: =vlookup(G6,D6:E175,1) -> ALLAll Social (FB + Google)Unsubscribe from all Everyday Rewards communications
A7: ALL | B7: Email | C7: Exclusive offers and promotions | D7: =CONCATENATE(A7,B7,C7) -> ALLEmailExclusive offers and promotions | E7: Ex Optout | G7: ALLEmailExclusive offers and promotions | H7: =vlookup(G7,D7:E176,1) -> ALLEmailExclusive offers and promotions
A8: ALL | B8: Rewards App | C8: Exclusive offers and promotions | D8: =CONCATENATE(A8,B8,C8) -> ALLRewards AppExclusive offers and promotions | E8: Inc All | G8: ALLRewards AppExclusive offers and promotions | H8: =vlookup(G8,D8:E177,1) -> ALLAll Social (FB + Google)Age < 18 years
A9: ALL | B9: Push | C9: Exclusive offers and promotions | D9: =CONCATENATE(A9,B9,C9) -> ALLPushExclusive offers and promotions | E9: Inc All
A10: ALL | B10: All Social (FB + Google) | C10: Exclusive offers and promotions | D10: =CONCATENATE(A10,B10,C10) -> ALLAll Social (FB + Google)Exclusive offers and promotions | E10: Inc All
A11: ALL | B11: Email | C11: Woolworths Supermarkets | D11: =CONCATENATE(A11,B11,C11) -> ALLEmailWoolworths Supermarkets | E11: Ex Optout
A12: ALL | B12: Rewards App | C12: Woolworths Supermarkets | D12: =CONCATENATE(A12,B12,C12) -> ALLRewards AppWoolworths Supermarkets | E12: Inc All
A13: ALL | B13: Push | C13: Woolworths Supermarkets | D13: =CONCATENATE(A13,B13,C13) -> ALLPushWoolworths Supermarkets | E13: Inc All
A14: ALL | B14: All Social (FB + Google) | C14: Woolworths Supermarkets | D14: =CONCATENATE(A14,B14,C14) -> ALLAll Social (FB + Google)Woolworths Supermarkets | E14: Inc All
A15: ALL | B15: Email | C15: BWS | D15: =CONCATENATE(A15,B15,C15) -> ALLEmailBWS | E15: Ex Optout
A16: ALL | B16: Rewards App | C16: BWS | D16: =CONCATENATE(A16,B16,C16) -> ALLRewards AppBWS | E16: Inc All
A17: ALL | B17: Push | C17: BWS | D17: =CONCATENATE(A17,B17,C17) -> ALLPushBWS | E17: Inc All
A18: ALL | B18: All Social (FB + Google) | C18: BWS | D18: =CONCATENATE(A18,B18,C18) -> ALLAll Social (FB + Google)BWS | E18: Inc All
A19: ALL | B19: Email | C19: Liquor Offers | D19: =CONCATENATE(A19,B19,C19) -> ALLEmailLiquor Offers | E19: Ex Optout
A20: ALL | B20: Rewards App | C20: Liquor Offers | D20: =CONCATENATE(A20,B20,C20) -> ALLRewards AppLiquor Offers | E20: Ex Optout
... A82: ALL | B82: All Social (FB + Google) | C82: Contact preference (website) - email | D82: =CONCATENATE(A82,B82,C82) -> ALLAll Social (FB + Google)Contact preference (website) - email | E82: Inc All
A83: ALL | B83: Email | C83: Cancelled Woolworths Reward Card | D83: =CONCATENATE(A83,B83,C83) -> ALLEmailCancelled Woolworths Reward Card | E83: TRUE
A84: ALL | B84: Rewards App | C84: Cancelled Woolworths Reward Card | D84: =CONCATENATE(A84,B84,C84) -> ALLRewards AppCancelled Woolworths Reward Card | E84: TRUE
A85: ALL | B85: Push | C85: Cancelled Woolworths Reward Card | D85: =CONCATENATE(A85,B85,C85) -> ALLPushCancelled Woolworths Reward Card | E85: TRUE
A86: ALL | B86: All Social (FB + Google) | C86: Cancelled Woolworths Reward Card | D86: =CONCATENATE(A86,B86,C86) -> ALLAll Social (FB + Google)Cancelled Woolworths Reward Card | E86: TRUE
A87: ALL | B87: Email | C87: Deceased | D87: =CONCATENATE(A87,B87,C87) -> ALLEmailDeceased | E87: TRUE
A88: ALL | B88: Rewards App | C88: Deceased | D88: =CONCATENATE(A88,B88,C88) -> ALLRewards AppDeceased | E88: TRUE
A89: ALL | B89: Push | C89: Deceased | D89: =CONCATENATE(A89,B89,C89) -> ALLPushDeceased | E89: TRUE
A90: ALL | B90: All Social (FB + Google) | C90: Deceased | D90: =CONCATENATE(A90,B90,C90) -> ALLAll Social (FB + Google)Deceased | E90: TRUE
A91: ALL | B91: Email | C91: Age < 16 years | D91: =CONCATENATE(A91,B91,C91) -> ALLEmailAge < 16 years | E91: TRUE
A92: ALL | B92: Rewards App | C92: Age < 16 years | D92: =CONCATENATE(A92,B92,C92) -> ALLRewards AppAge < 16 years | E92: TRUE
A93: ALL | B93: Push | C93: Age < 16 years | D93: =CONCATENATE(A93,B93,C93) -> ALLPushAge < 16 years | E93: TRUE
A94: ALL | B94: All Social (FB + Google) | C94: Age < 16 years | D94: =CONCATENATE(A94,B94,C94) -> ALLAll Social (FB + Google)Age < 16 years | E94: TRUE
... A154: ALL | B154: All Social (FB + Google) | C154: Non Engaged (Has not clicked email in past 26 weeks) | D154: =CONCATENATE(A154,B154,C154) -> ALLAll Social (FB + Google)Non Engaged (Has not clicked email in past 26 weeks) | E154: FALSE
A155: ALL | B155: Unsub Parameter | C155: Supers | D155: =CONCATENATE(A155,B155,C155) -> ALLUnsub ParameterSupers | E155: [woolworths] - Woolworths Supermarkets
A156: ALL | B156: Unsub Parameter | C156: BWS | D156: =CONCATENATE(A156,B156,C156) -> ALLUnsub ParameterBWS | E156: [bws] - BWS
A157: ALL | B157: Unsub Parameter | C157: Big W | D157: =CONCATENATE(A157,B157,C157) -> ALLUnsub ParameterBig W | E157: [bigw] - BIG W
A158: ALL | B158: Unsub Parameter | C158: EG | D158: =CONCATENATE(A158,B158,C158) -> ALLUnsub ParameterEG | E158: [petrol] - Fuel
A159: ALL | B159: Unsub Parameter | C159: Caltex | D159: =CONCATENATE(A159,B159,C159) -> ALLUnsub ParameterCaltex | E159: [petrol] - Fuel
A160: ALL | B160: Unsub Parameter | C160: PA | D160: =CONCATENATE(A160,B160,C160) -> ALLUnsub ParameterPA | E160: [programaffiliates] - Program Affiliates
A161: ALL | B161: Unsub Parameter | C161: XSell | D161: =CONCATENATE(A161,B161,C161) -> ALLUnsub ParameterXSell | E161: [all] - Unsubscribe from all Everyday Rewards communications
...

Sheet Copy of Preference Lookup
A2: Key 1 - Banner | B2: Key 2 - Channel | C2: Key 3 - Line Item | D2: CompoundKey | E2: Value
A3: ALL | B3: Email | C3: Unsubscribe from all Everyday Rewards communications | D3: =CONCATENATE(A3,B3,C3) -> ALLEmailUnsubscribe from all Everyday Rewards communications | E3: Ex Optout | G3: ALLEmailUnsubscribe from all Everyday Rewards communications | H3: =vlookup(G3,D3:E80,2,false) -> Ex Optout
A4: ALL | B4: Rewards App | C4: Unsubscribe from all Everyday Rewards communications | D4: =CONCATENATE(A4,B4,C4) -> ALLRewards AppUnsubscribe from all Everyday Rewards communications | E4: Inc All | G4: ALLRewards AppUnsubscribe from all Everyday Rewards communications | H4: =vlookup(G4,D4:E81,1) -> ALLAll Social (FB + Google)Dry Postcodes (for Liquor Campaigns)
A5: ALL | B5: All Social (FB + Google) | C5: Unsubscribe from all Everyday Rewards communications | D5: =CONCATENATE(A5,B5,C5) -> ALLAll Social (FB + Google)Unsubscribe from all Everyday Rewards communications | E5: Inc All | G5: ALLAll Social (FB + Google)Unsubscribe from all Everyday Rewards communications | H5: =vlookup(G5,D5:E82,1) -> ALLAll Social (FB + Google)Competitor Email (Add Domain here for Ref)
A6: ALL | B6: Email | C6: Exclusive offers and promotions | D6: =CONCATENATE(A6,B6,C6) -> ALLEmailExclusive offers and promotions | E6: Ex Optout | G6: ALLEmailExclusive offers and promotions | H6: =vlookup(G6,D6:E83,1) -> ALLAll Social (FB + Google)Overseas
A7: ALL | B7: Rewards App | C7: Exclusive offers and promotions | D7: =CONCATENATE(A7,B7,C7) -> ALLRewards AppExclusive offers and promotions | E7: Inc All | G7: ALLRewards AppExclusive offers and promotions | H7: =vlookup(G7,D7:E84,1) -> ALLEmail
A8: ALL | B8: All Social (FB + Google) | C8: Exclusive offers and promotions | D8: =CONCATENATE(A8,B8,C8) -> ALLAll Social (FB + Google)Exclusive offers and promotions | E8: Inc All
A9: ALL | B9: Email | C9: Woolworths Supermarkets | D9: =CONCATENATE(A9,B9,C9) -> ALLEmailWoolworths Supermarkets | E9: Ex Optout
A10: ALL | B10: Rewards App | C10: Woolworths Supermarkets | D10: =CONCATENATE(A10,B10,C10) -> ALLRewards AppWoolworths Supermarkets | E10: Inc All
A11: ALL | B11: All Social (FB + Google) | C11: Woolworths Supermarkets | D11: =CONCATENATE(A11,B11,C11) -> ALLAll Social (FB + Google)Woolworths Supermarkets | E11: Inc All
A12: ALL | B12: Email | C12: BWS | D12: =CONCATENATE(A12,B12,C12) -> ALLEmailBWS | E12: Ex Optout
A13: ALL | B13: Rewards App | C13: BWS | D13: =CONCATENATE(A13,B13,C13) -> ALLRewards AppBWS | E13: Inc All
A14: ALL | B14: All Social (FB + Google) | C14: BWS | D14: =CONCATENATE(A14,B14,C14) -> ALLAll Social (FB + Google)BWS | E14: Inc All
A15: ALL | B15: Email | C15: No liquor offers and promotions | D15: =CONCATENATE(A15,B15,C15) -> ALLEmailNo liquor offers and promotions | E15: Ex Optin
A16: ALL | B16: Rewards App | C16: No liquor offers and promotions | D16: =CONCATENATE(A16,B16,C16) -> ALLRewards AppNo liquor offers and promotions | E16: Ex Optin
A17: ALL | B17: All Social (FB + Google) | C17: No liquor offers and promotions | D17: =CONCATENATE(A17,B17,C17) -> ALLAll Social (FB + Google)No liquor offers and promotions | E17: Ex Optin
A18: ALL | B18: Email | C18: Big W | D18: =CONCATENATE(A18,B18,C18) -> ALLEmailBig W | E18: Ex Optout
A19: ALL | B19: Rewards App | C19: Big W | D19: =CONCATENATE(A19,B19,C19) -> ALLRewards AppBig W | E19: Inc All
... A80: ALL | B80: All Social (FB + Google) | C80: Staff | D80: =CONCATENATE(A80,B80,C80) -> ALLAll Social (FB + Google)Staff | E80: YES
A81: ALL | B81: Email | D81: =CONCATENATE(A81,B81,C81) -> ALLEmail
A82: ALL | B82: Rewards App | D82: =CONCATENATE(A82,B82,C82) -> ALLRewards App
A83: ALL | B83: All Social (FB + Google) | D83: =CONCATENATE(A83,B83,C83) -> ALLAll Social (FB + Google)
A84: ALL | B84: Email | D84: =CONCATENATE(A84,B84,C84) -> ALLEmail
A85: ALL | B85: Rewards App | D85: =CONCATENATE(A85,B85,C85) -> ALLRewards App
A86: ALL | B86: All Social (FB + Google) | D86: =CONCATENATE(A86,B86,C86) -> ALLAll Social (FB + Google)
A87: ALL | B87: Email | D87: =CONCATENATE(A87,B87,C87) -> ALLEmail
A88: ALL | B88: Rewards App | D88: =CONCATENATE(A88,B88,C88) -> ALLRewards App
A89: ALL | B89: All Social (FB + Google) | D89: =CONCATENATE(A89,B89,C89) -> ALLAll Social (FB + Google)
A90: ALL | B90: Email | D90: =CONCATENATE(A90,B90,C90) -> ALLEmail
A91: ALL | B91: Rewards App | D91: =CONCATENATE(A91,B91,C91) -> ALLRewards App
A92: ALL | B92: All Social (FB + Google) | D92: =CONCATENATE(A92,B92,C92) -> ALLAll Social (FB + Google)
... A290: ALL | B290: All Social (FB + Google) | D290: =CONCATENATE(A290,B290,C290) -> ALLAll Social (FB + Google)

Sheet Version Control
B2: Version | C2: Date | D2: Updates
B4: v0.11 | C4: 43312 | D4: Change from one to three Data Brief Forms - one each for Woolworths Rewards and Frequent Shopper Club Customer Bases, Services Customer Bases, and Online Customer Bases, and other associated update
B5: v7 | C5: 44225 | D5: Baseline of automated data brief
B6: v7.1 | C6: 44236 | D6: Changed default value of "Email" + "Universal control group" combination to TRUE
B7: v7.2 | C7: 44305 | D7: Added conditional formatting that highlights overrides
B8: v7.3 | C8: 44323 | D8: Updated "no liquor offer" to "liquor offer"
B9: v7.4 | C9: 44404 | D9: Added options for Insurance (Services BU), and split-out partners
B12: v7.7 | C12: 44823 | D12: Change to ONL data brief and adding in new channel suitable for ONL environment
C13: 44840 | D13: Updated the Staff/Onboarding to be the normal tickbox
C14: 44861 | D14: Updated the RTL related offer matrix/migration some changes from 7.6 which were previously missing
B15: v7.9 | C15: 45251 | D15: Added placeholders for Milkrun and <new partner>. Script is not yet enabled for these two
D16: Added a standard exclusion for engaged (has not clicked L26W). By default this is ticked for e-mail

Sheet Original Brief
B2: Status: | C2: Initial Walkthrough 09Nov17
B4: Section Name: | C4: 2. Data Brief
B6: Brief: | C6: As below
B8: Notes: | C8: In Column B
B11: Guidance Text | D11: Instructions:
D12: Please make a copy of the Form and Save to your Google Drive as: <Campaign Code>_2.0. Data - Data Brief Form_<v0.x>
D13: Complete the Form inputs
D14: Please Select "In" = Include, "Ex" = Exclude, where applicable. If a Data Field isn't relevant to the Business Area or Campaign, leave it Blank
D15: Save the Form as a PDF by selecting: File > Download as > PDF document (.pdf)
D16: Upload to the Task in Simple
B18: Highlight OR Fade Sections Below (with Underlined Business Area Headings) that Are OR Aren't relevant | D18: Please Note that the Data Brief Form is for all Business Areas
D19: The Form has Conditional Formatting to highlight the sections relevant to your Campaign
D22: Campaign Code
B23: Free Text | D23: e.g.: OSP-1001
B25: Hyperlink to relevant place in form | C25: A | D25: Target Audience Selection
B26: " | C26: A1 | D26: Business Area
B27: " | C27: A2 | D27: Member Status
B28: " | C28: A3 | D28: Business Area Subscriptions (by Channel)
B29: " | C29: A4 | D29: Channel Subscriptions (by Channel)
B31: " | C31: A5 | D31: Campaign Inclusions
B33: " | C33: A6 | D33: Global Exclusions
B34: " | C34: A7 | D34: Standard Exclusions
B35: " | C35: A8 | D35: Campaign Exclusions
B37: " | C37: A9 | D37: Duplicates
B39: " | C39: B | D39: Target Audience Segmentation
B40: " | C40: B1 | D40: Target Audience Cells
... B45: " | C45: D | D45: Analysis and Files
C48: A | D48: Target Audience Selection
C50: A1 | D50: Business Area
B51: Guidance Text | D51: Target Customer Base
B52: Multi Select - "In" OR Blank | C52: - | D52: Woolworths Rewards
C53: - | D53: Woolworths Rewards Plus
C54: - | D54: Frequent Shoppers Club [FSC]
C55: - | D55: Woolworths Online [ONL]
C56: - | D56: Services - Cards [SER]
C57: - | D57: Services - Insurance [SER]
C58: - | D58: Services - Mobile [SER]
C61: A2 | D61: Member Status
B62: Multi Select - "In" OR Blank | C62: - | D62: Member | Q62: Notes: Registered and Active
C63: - | D63: Non-Member
...

Sheet Split Brief
B5: Instructions:
B6: - Please make a copy of the Form and Save to your Google Drive as: <Campaign Code>_7.3 Reporting - Split Reporting Form_<v0.x>
B7: - Complete the Form inputs
B8: - Save the Form as a PDF by selecting: File > Download as > PDF document (.pdf)
B9: - Upload to the Task in Simple
B12: Reporting - Split Reporting
B14: Reference | C14: Description
B16: Split 1 | C16: Total | J16: e.g.: Split by Target Audience Cells
B17: Split 2 | C17: By non Marketable segments (split out by lapsed, inactive, New) | J17: e.g.: Split by Target Audience Age Groups: <30 Years and ≥ 30 Years
B18: Split 3 | C18: By marketable segments (split out by lapsed, inactive, new) | J18: e.g.: Split by Offer: 2,000 Points vs. $10
B19: Split 4 | C19: By segment total ( split out by lapsed, inactive, new). | J19: e.g.: Split by Creative A and Creative B
B20: Split 5 | C20: By marketable totals | J20: e.g.: Tag by State
B21: Split 6 | C21: By non marketbale totals
B24: Please include any additional comments or instructions:
